Workbook

Sheet Catálogo de Máquinas
A1: SECTOR | B1: TIPO | C1: ID MÁQ | D1: NOMBRE | E1: LOCAL | F1: LADO | G1: MODELO | H1: SERIE | I1: ACTIVO | J1: ADQUISICION | K1: EXCEL_ID | L1: GRP_TEAR | M1: G_CMEST
A2: HILANDERIA | B2: APERTURA | C2: 50102 | D2: APERTURA | E2: 2 | F2: U | G2: --- | H2: --- | I2: SI | J2: --- | K2: ---
A3: HILANDERIA | B3: APERTURA | C3: 50103 | D3: APERTURA | E3: 2 | F3: U | G3: --- | H3: --- | I3: SI | J3: --- | K3: ---
A4: HILANDERIA | B4: CARDA | C4: 50201 | D4: TRUTZSCHLER | E4: 1 | F4: U | G4: --- | H4: --- | I4: SI | J4: --- | K4: ---
A5: HILANDERIA | B5: CARDA | C5: 50202 | D5: TRUTZSCHLER | E5: 2 | F5: U | G5: --- | H5: --- | I5: SI | J5: --- | K5: ---
A6: HILANDERIA | B6: CARDA | C6: 50203 | D6: TRUTZSCHLER | E6: 3 | F6: U | G6: --- | H6: --- | I6: SI | J6: --- | K6: ---
A7: HILANDERIA | B7: CARDA | C7: 50204 | D7: TRUTZSCHLER | E7: 4 | F7: U | G7: --- | H7: --- | I7: SI | J7: --- | K7: ---
A8: HILANDERIA | B8: CARDA | C8: 50205 | D8: TRUTZSCHLER | E8: 5 | F8: U | G8: --- | H8: --- | I8: SI | J8: --- | K8: ---
A9: HILANDERIA | B9: CARDA | C9: 50206 | D9: TRUTZSCHLER | E9: 6 | F9: U | G9: --- | H9: --- | I9: SI | J9: --- | K9: ---
A10: HILANDERIA | B10: CARDA | C10: 50207 | D10: TRUTZSCHLER | E10: 7 | F10: U | G10: --- | H10: --- | I10: SI | J10: --- | K10: ---
A11: HILANDERIA | B11: CARDA | C11: 50208 | D11: RIETER | E11: 8 | F11: U | G11: --- | H11: --- | I11: SI | J11: --- | K11: ---
A12: HILANDERIA | B12: CARDA | C12: 50209 | D12: RIETER | E12: 9 | F12: U | G12: --- | H12: --- | I12: SI | J12: --- | K12: ---
A13: HILANDERIA | B13: CARDA | C13: 50210 | D13: RIETER | E13: 10 | F13: U | G13: --- | H13: --- | I13: SI | J13: --- | K13: ---
... A36: HILANDERIA | B36: FILTRO | C36: 50703 | D36: FILTRO | E36: 3 | F36: U | G36: --- | H36: --- | I36: SI | J36: --- | K36: ---
A37: TEJEDURIA | B37: URDIDORA | C37: 15001 | D37: URDIDORA | E37: 531 | F37: U | G37: BEN DIRECT | H37: --- | I37: SI | J37: 12/2/2008 | K37: 1
A38: TEJEDURIA | B38: INDIGO | C38: 25001 | D38: INDIGO | E38: 532 | F38: U | G38: BENNINGER | H38: --- | I38: SI | J38: 12/2/2008 | K38: 2
A39: TEJEDURIA | B39: TELAR | C39: 35001 | D39: TOYOTA | E39: 534 | F39: U | G39: JA2S-190TP-EF-T710 | H39: --- | I39: SI | J39: 12/2/2008 | K39: 3 | L39: =VLOOKUP(C39,Hoja1!A:C,2,FALSE) -> 0305 | M39: =VLOOKUP(C39,Hoja1!A:C,3,FALSE) -> 01
A40: TEJEDURIA | B40: TELAR | C40: 35002 | D40: TOYOTA | E40: 534 | F40: U | G40: JA2S-190TP-EF-T710 | H40: --- | I40: SI | J40: 12/2/2008 | K40: 3 | L40: =VLOOKUP(C40,Hoja1!A:C,2,FALSE) -> 0305 | M40: =VLOOKUP(C40,Hoja1!A:C,3,FALSE) -> 01
A41: TEJEDURIA | B41: TELAR | C41: 35003 | D41: TOYOTA | E41: 534 | F41: U | G41: JA2S-190TP-EF-T710 | H41: --- | I41: SI | J41: 8/11/2007 | K41: 3 | L41: =VLOOKUP(C41,Hoja1!A:C,2,FALSE) -> 0305 | M41: =VLOOKUP(C41,Hoja1!A:C,3,FALSE) -> 01
A42: TEJEDURIA | B42: TELAR | C42: 35004 | D42: TOYOTA | E42: 534 | F42: U | G42: JA2S-190TP-EF-T710 | H42: --- | I42: SI | J42: 8/11/2007 | K42: 3 | L42: =VLOOKUP(C42,Hoja1!A:C,2,FALSE) -> 0305 | M42: =VLOOKUP(C42,Hoja1!A:C,3,FALSE) -> 01
A43: TEJEDURIA | B43: TELAR | C43: 35005 | D43: TOYOTA | E43: 534 | F43: U | G43: JA2S-190TP-EF-T710 | H43: --- | I43: SI | J43: 8/11/2007 | K43: 3 | L43: =VLOOKUP(C43,Hoja1!A:C,2,FALSE) -> 0306 | M43: =VLOOKUP(C43,Hoja1!A:C,3,FALSE) -> 02
A44: TEJEDURIA | B44: TELAR | C44: 35006 | D44: TOYOTA | E44: 534 | F44: U | G44: JA2S-190TP-EF-T710 | H44: --- | I44: SI | J44: 9/10/2007 | K44: 3 | L44: =VLOOKUP(C44,Hoja1!A:C,2,FALSE) -> 0306 | M44: =VLOOKUP(C44,Hoja1!A:C,3,FALSE) -> 02
A45: TEJEDURIA | B45: TELAR | C45: 35007 | D45: TOYOTA | E45: 534 | F45: U | G45: JA2S-190TP-EF-T710 | H45: --- | I45: SI | J45: 9/10/2007 | K45: 3 | L45: =VLOOKUP(C45,Hoja1!A:C,2,FALSE) -> 0306 | M45: =VLOOKUP(C45,Hoja1!A:C,3,FALSE) -> 02
A46: TEJEDURIA | B46: TELAR | C46: 35008 | D46: TOYOTA | E46: 534 | F46: U | G46: JA2S-190TP-EF-T710 | H46: --- | I46: SI | J46: 9/10/2007 | K46: 3 | L46: =VLOOKUP(C46,Hoja1!A:C,2,FALSE) -> 0306 | M46: =VLOOKUP(C46,Hoja1!A:C,3,FALSE) -> 02
A47: TEJEDURIA | B47: TELAR | C47: 35009 | D47: TOYOTA | E47: 534 | F47: U | G47: JA2S-190TP-EF-T710 | H47: --- | I47: SI | J47: 9/10/2007 | K47: 3 | L47: =VLOOKUP(C47,Hoja1!A:C,2,FALSE) -> 0305 | M47: =VLOOKUP(C47,Hoja1!A:C,3,FALSE) -> 01
A48: TEJEDURIA | B48: TELAR | C48: 35010 | D48: TOYOTA | E48: 534 | F48: U | G48: JA2S-190TP-EF-T710 | H48: --- | I48: SI | J48: 9/10/2007 | K48: 3 | L48: =VLOOKUP(C48,Hoja1!A:C,2,FALSE) -> 0305 | M48: =VLOOKUP(C48,Hoja1!A:C,3,FALSE) -> 01
A49: TEJEDURIA | B49: TELAR | C49: 35011 | D49: TOYOTA | E49: 534 | F49: U | G49: JA2S-190TP-EF-T710 | H49: --- | I49: SI | J49: 9/10/2007 | K49: 3 | L49: =VLOOKUP(C49,Hoja1!A:C,2,FALSE) -> 0305 | M49: =VLOOKUP(C49,Hoja1!A:C,3,FALSE) -> 01
A50: TEJEDURIA | B50: TELAR | C50: 35012 | D50: TOYOTA | E50: 534 | F50: U | G50: JA2S-190TP-EF-T710 | H50: --- | I50: SI | J50: 9/10/2008 | K50: 3 | L50: =VLOOKUP(C50,Hoja1!A:C,2,FALSE) -> 0305 | M50: =VLOOKUP(C50,Hoja1!A:C,3,FALSE) -> 01
... A118: TEJEDURIA | B118: TELAR | C118: 35080 | D118: TOYOTA | E118: 534 | F118: U | G118: JA2S-190TP-EF-T710 | H118: --- | I118: SI | J118: 14/10/2011 | K118: 3 | L118: =VLOOKUP(C118,Hoja1!A:C,2,FALSE) -> 0302 | M118: =VLOOKUP(C118,Hoja1!A:C,3,FALSE) -> 02
A119: TEJEDURIA | B119: TELAR | C119: 53081 | D119: TOYOTA | E119: 534 | F119: U | G119: JA2S-190TP-EF-T710 | H119: --- | I119: NO | J119: 31/1/2017 | K119: 3
A120: TEJEDURIA | B120: TELAR | C120: 53082 | D120: TOYOTA | E120: 534 | F120: U | G120: JA2S-190TP-EF-T710 | H120: --- | I120: NO | J120: 31/1/2017 | K120: 3
A121: TEJEDURIA | B121: TELAR | C121: 53083 | D121: TOYOTA | E121: 534 | F121: U | G121: JA2S-190TP-EF-T710 | H121: --- | I121: NO | J121: 31/1/2017 | K121: 3
A122: TEJEDURIA | B122: TELAR | C122: 53084 | D122: TOYOTA | E122: 534 | F122: U | G122: JA2S-190TP-EF-T710 | H122: --- | I122: NO | J122: 31/1/2017 | K122: 3
A123: TEJEDURIA | B123: TELAR | C123: 53085 | D123: TOYOTA | E123: 534 | F123: U | G123: JA2S-190TP-EF-T710 | H123: --- | I123: NO | J123: 31/1/2017 | K123: 3
A124: TEJEDURIA | B124: TELAR | C124: 53086 | D124: TOYOTA | E124: 534 | F124: U | G124: JA2S-190TP-EF-T710 | H124: --- | I124: NO | J124: 31/1/2017 | K124: 3
A125: TEJEDURIA | B125: TELAR | C125: 53087 | D125: TOYOTA | E125: 534 | F125: U | G125: JA2S-190TP-EF-T710 | H125: --- | I125: NO | J125: 31/1/2017 | K125: 3
A126: TEJEDURIA | B126: TELAR | C126: 53088 | D126: TOYOTA | E126: 534 | F126: U | G126: JA2S-190TP-EF-T710 | H126: --- | I126: NO | J126: 31/1/2017 | K126: 3
A127: TEJEDURIA | B127: REVISADORA | C127: 85001 | D127: MESA | E127: 547 | F127: U | G127: AVELINO | H127: --- | I127: SI | J127: 12/2/2008 | K127: 8
A128: TEJEDURIA | B128: REVISADORA | C128: 85002 | D128: MESA | E128: 547 | F128: U | G128: AVELINO | H128: --- | I128: SI | J128: 12/2/2008 | K128: 8
A129: TEJEDURIA | B129: REVISADORA | C129: 85003 | D129: MESA | E129: 547 | F129: U | G129: AVELINO | H129: --- | I129: SI | J129: 12/2/2008 | K129: 8
...

Sheet Hoja1
A1: MAQUINA | B1: GRP_TEAR | C1: G_CMEST
A2: 35001 | B2: 0305 | C2: 01
A3: 35002 | B3: 0305 | C3: 01
A4: 35003 | B4: 0305 | C4: 01
A5: 35004 | B5: 0305 | C5: 01
A6: 35005 | B6: 0306 | C6: 02
A7: 35006 | B7: 0306 | C7: 02
A8: 35007 | B8: 0306 | C8: 02
A9: 35008 | B9: 0306 | C9: 02
A10: 35009 | B10: 0305 | C10: 01
A11: 35010 | B11: 0305 | C11: 01
A12: 35011 | B12: 0305 | C12: 01
A13: 35012 | B13: 0305 | C13: 01
... A81: 35080 | B81: 0302 | C81: 02
